2013-12-16 11:45:51,400 ERROR: Exception on /static/img/google.png [GET] [in /usr/local/lib/python2.7/dist-packages/flask/app.py:1423]
Traceback (most recent call last):
  File "/usr/local/lib/python2.7/dist-packages/flask/app.py", line 1817, in wsgi_app
    response = self.full_dispatch_request()
  File "/usr/local/lib/python2.7/dist-packages/flask/app.py", line 1477, in full_dispatch_request
    rv = self.handle_user_exception(e)
  File "/usr/local/lib/python2.7/dist-packages/flask/app.py", line 1381, in handle_user_exception
    reraise(exc_type, exc_value, tb)
  File "/usr/local/lib/python2.7/dist-packages/flask/app.py", line 1475, in full_dispatch_request
    rv = self.dispatch_request()
  File "/usr/local/lib/python2.7/dist-packages/flask/app.py", line 1461, in dispatch_request
    return self.view_functions[rule.endpoint](**req.view_args)
  File "/usr/local/lib/python2.7/dist-packages/flask/helpers.py", line 822, in send_static_file
    cache_timeout=cache_timeout)
  File "/usr/local/lib/python2.7/dist-packages/flask/helpers.py", line 616, in send_from_directory
    return send_file(filename, **options)
  File "/usr/local/lib/python2.7/dist-packages/flask/helpers.py", line 520, in send_file
    file = open(filename, 'rb')
IOError: [Errno 13] Permission denied: u'/var/www/flaskr/app/static/img/google.png'
2013-12-16 11:45:51,403 ERROR: Exception on /static/img/yahoo.png [GET] [in /usr/local/lib/python2.7/dist-packages/flask/app.py:1423]
Traceback (most recent call last):
  File "/usr/local/lib/python2.7/dist-packages/flask/app.py", line 1817, in wsgi_app
    response = self.full_dispatch_request()
  File "/usr/local/lib/python2.7/dist-packages/flask/app.py", line 1477, in full_dispatch_request
    rv = self.handle_user_exception(e)
  File "/usr/local/lib/python2.7/dist-packages/flask/app.py", line 1381, in handle_user_exception
    reraise(exc_type, exc_value, tb)
  File "/usr/local/lib/python2.7/dist-packages/flask/app.py", line 1475, in full_dispatch_request
    rv = self.dispatch_request()
  File "/usr/local/lib/python2.7/dist-packages/flask/app.py", line 1461, in dispatch_request
    return self.view_functions[rule.endpoint](**req.view_args)
  File "/usr/local/lib/python2.7/dist-packages/flask/helpers.py", line 822, in send_static_file
    cache_timeout=cache_timeout)
  File "/usr/local/lib/python2.7/dist-packages/flask/helpers.py", line 616, in send_from_directory
    return send_file(filename, **options)
  File "/usr/local/lib/python2.7/dist-packages/flask/helpers.py", line 520, in send_file
    file = open(filename, 'rb')
IOError: [Errno 13] Permission denied: u'/var/www/flaskr/app/static/img/yahoo.png'
2013-12-16 11:48:19,414 ERROR: Exception on /static/img/aol.png [GET] [in /usr/local/lib/python2.7/dist-packages/flask/app.py:1423]
Traceback (most recent call last):
  File "/usr/local/lib/python2.7/dist-packages/flask/app.py", line 1817, in wsgi_app
    response = self.full_dispatch_request()
  File "/usr/local/lib/python2.7/dist-packages/flask/app.py", line 1477, in full_dispatch_request
    rv = self.handle_user_exception(e)
  File "/usr/local/lib/python2.7/dist-packages/flask/app.py", line 1381, in handle_user_exception
    reraise(exc_type, exc_value, tb)
  File "/usr/local/lib/python2.7/dist-packages/flask/app.py", line 1475, in full_dispatch_request
    rv = self.dispatch_request()
  File "/usr/local/lib/python2.7/dist-packages/flask/app.py", line 1461, in dispatch_request
    return self.view_functions[rule.endpoint](**req.view_args)
  File "/usr/local/lib/python2.7/dist-packages/flask/helpers.py", line 822, in send_static_file
    cache_timeout=cache_timeout)
  File "/usr/local/lib/python2.7/dist-packages/flask/helpers.py", line 616, in send_from_directory
    return send_file(filename, **options)
  File "/usr/local/lib/python2.7/dist-packages/flask/helpers.py", line 520, in send_file
    file = open(filename, 'rb')
IOError: [Errno 13] Permission denied: u'/var/www/flaskr/app/static/img/aol.png'
2013-12-16 11:48:19,577 ERROR: Exception on /static/img/yahoo.png [GET] [in /usr/local/lib/python2.7/dist-packages/flask/app.py:1423]
Traceback (most recent call last):
  File "/usr/local/lib/python2.7/dist-packages/flask/app.py", line 1817, in wsgi_app
    response = self.full_dispatch_request()
  File "/usr/local/lib/python2.7/dist-packages/flask/app.py", line 1477, in full_dispatch_request
    rv = self.handle_user_exception(e)
  File "/usr/local/lib/python2.7/dist-packages/flask/app.py", line 1381, in handle_user_exception
    reraise(exc_type, exc_value, tb)
  File "/usr/local/lib/python2.7/dist-packages/flask/app.py", line 1475, in full_dispatch_request
    rv = self.dispatch_request()
  File "/usr/local/lib/python2.7/dist-packages/flask/app.py", line 1461, in dispatch_request
    return self.view_functions[rule.endpoint](**req.view_args)
  File "/usr/local/lib/python2.7/dist-packages/flask/helpers.py", line 822, in send_static_file
    cache_timeout=cache_timeout)
  File "/usr/local/lib/python2.7/dist-packages/flask/helpers.py", line 616, in send_from_directory
    return send_file(filename, **options)
  File "/usr/local/lib/python2.7/dist-packages/flask/helpers.py", line 520, in send_file
    file = open(filename, 'rb')
IOError: [Errno 13] Permission denied: u'/var/www/flaskr/app/static/img/yahoo.png'
2013-12-16 11:48:19,589 ERROR: Exception on /static/img/flickr.png [GET] [in /usr/local/lib/python2.7/dist-packages/flask/app.py:1423]
Traceback (most recent call last):
  File "/usr/local/lib/python2.7/dist-packages/flask/app.py", line 1817, in wsgi_app
    response = self.full_dispatch_request()
  File "/usr/local/lib/python2.7/dist-packages/flask/app.py", line 1477, in full_dispatch_request
    rv = self.handle_user_exception(e)
  File "/usr/local/lib/python2.7/dist-packages/flask/app.py", line 1381, in handle_user_exception
    reraise(exc_type, exc_value, tb)
  File "/usr/local/lib/python2.7/dist-packages/flask/app.py", line 1475, in full_dispatch_request
    rv = self.dispatch_request()
  File "/usr/local/lib/python2.7/dist-packages/flask/app.py", line 1461, in dispatch_request
    return self.view_functions[rule.endpoint](**req.view_args)
  File "/usr/local/lib/python2.7/dist-packages/flask/helpers.py", line 822, in send_static_file
    cache_timeout=cache_timeout)
  File "/usr/local/lib/python2.7/dist-packages/flask/helpers.py", line 616, in send_from_directory
    return send_file(filename, **options)
  File "/usr/local/lib/python2.7/dist-packages/flask/helpers.py", line 520, in send_file
    file = open(filename, 'rb')
IOError: [Errno 13] Permission denied: u'/var/www/flaskr/app/static/img/flickr.png'
2013-12-16 11:48:19,592 ERROR: Exception on /static/img/myopenid.png [GET] [in /usr/local/lib/python2.7/dist-packages/flask/app.py:1423]
Traceback (most recent call last):
  File "/usr/local/lib/python2.7/dist-packages/flask/app.py", line 1817, in wsgi_app
    response = self.full_dispatch_request()
  File "/usr/local/lib/python2.7/dist-packages/flask/app.py", line 1477, in full_dispatch_request
    rv = self.handle_user_exception(e)
  File "/usr/local/lib/python2.7/dist-packages/flask/app.py", line 1381, in handle_user_exception
    reraise(exc_type, exc_value, tb)
  File "/usr/local/lib/python2.7/dist-packages/flask/app.py", line 1475, in full_dispatch_request
    rv = self.dispatch_request()
  File "/usr/local/lib/python2.7/dist-packages/flask/app.py", line 1461, in dispatch_request
    return self.view_functions[rule.endpoint](**req.view_args)
  File "/usr/local/lib/python2.7/dist-packages/flask/helpers.py", line 822, in send_static_file
    cache_timeout=cache_timeout)
  File "/usr/local/lib/python2.7/dist-packages/flask/helpers.py", line 616, in send_from_directory
    return send_file(filename, **options)
  File "/usr/local/lib/python2.7/dist-packages/flask/helpers.py", line 520, in send_file
    file = open(filename, 'rb')
IOError: [Errno 13] Permission denied: u'/var/www/flaskr/app/static/img/myopenid.png'
2013-12-16 11:48:21,746 ERROR: Exception on /static/css/bootstrap.min.css [GET] [in /usr/local/lib/python2.7/dist-packages/flask/app.py:1423]
Traceback (most recent call last):
  File "/usr/local/lib/python2.7/dist-packages/flask/app.py", line 1817, in wsgi_app
    response = self.full_dispatch_request()
  File "/usr/local/lib/python2.7/dist-packages/flask/app.py", line 1477, in full_dispatch_request
    rv = self.handle_user_exception(e)
  File "/usr/local/lib/python2.7/dist-packages/flask/app.py", line 1381, in handle_user_exception
    reraise(exc_type, exc_value, tb)
  File "/usr/local/lib/python2.7/dist-packages/flask/app.py", line 1475, in full_dispatch_request
    rv = self.dispatch_request()
  File "/usr/local/lib/python2.7/dist-packages/flask/app.py", line 1461, in dispatch_request
    return self.view_functions[rule.endpoint](**req.view_args)
  File "/usr/local/lib/python2.7/dist-packages/flask/helpers.py", line 822, in send_static_file
    cache_timeout=cache_timeout)
  File "/usr/local/lib/python2.7/dist-packages/flask/helpers.py", line 616, in send_from_directory
    return send_file(filename, **options)
  File "/usr/local/lib/python2.7/dist-packages/flask/helpers.py", line 520, in send_file
    file = open(filename, 'rb')
IOError: [Errno 13] Permission denied: u'/var/www/flaskr/app/static/css/bootstrap.min.css'
2013-12-16 11:48:21,755 ERROR: Exception on /static/js/bootstrap.min.js [GET] [in /usr/local/lib/python2.7/dist-packages/flask/app.py:1423]
Traceback (most recent call last):
  File "/usr/local/lib/python2.7/dist-packages/flask/app.py", line 1817, in wsgi_app
    response = self.full_dispatch_request()
  File "/usr/local/lib/python2.7/dist-packages/flask/app.py", line 1477, in full_dispatch_request
    rv = self.handle_user_exception(e)
  File "/usr/local/lib/python2.7/dist-packages/flask/app.py", line 1381, in handle_user_exception
    reraise(exc_type, exc_value, tb)
  File "/usr/local/lib/python2.7/dist-packages/flask/app.py", line 1475, in full_dispatch_request
    rv = self.dispatch_request()
  File "/usr/local/lib/python2.7/dist-packages/flask/app.py", line 1461, in dispatch_request
    return self.view_functions[rule.endpoint](**req.view_args)
  File "/usr/local/lib/python2.7/dist-packages/flask/helpers.py", line 822, in send_static_file
    cache_timeout=cache_timeout)
  File "/usr/local/lib/python2.7/dist-packages/flask/helpers.py", line 616, in send_from_directory
    return send_file(filename, **options)
  File "/usr/local/lib/python2.7/dist-packages/flask/helpers.py", line 520, in send_file
    file = open(filename, 'rb')
IOError: [Errno 13] Permission denied: u'/var/www/flaskr/app/static/js/bootstrap.min.js'
2013-12-16 11:48:21,765 ERROR: Exception on /static/js/moment.min.js [GET] [in /usr/local/lib/python2.7/dist-packages/flask/app.py:1423]
Traceback (most recent call last):
  File "/usr/local/lib/python2.7/dist-packages/flask/app.py", line 1817, in wsgi_app
    response = self.full_dispatch_request()
  File "/usr/local/lib/python2.7/dist-packages/flask/app.py", line 1477, in full_dispatch_request
    rv = self.handle_user_exception(e)
  File "/usr/local/lib/python2.7/dist-packages/flask/app.py", line 1381, in handle_user_exception
    reraise(exc_type, exc_value, tb)
  File "/usr/local/lib/python2.7/dist-packages/flask/app.py", line 1475, in full_dispatch_request
    rv = self.dispatch_request()
  File "/usr/local/lib/python2.7/dist-packages/flask/app.py", line 1461, in dispatch_request
    return self.view_functions[rule.endpoint](**req.view_args)
  File "/usr/local/lib/python2.7/dist-packages/flask/helpers.py", line 822, in send_static_file
    cache_timeout=cache_timeout)
  File "/usr/local/lib/python2.7/dist-packages/flask/helpers.py", line 616, in send_from_directory
    return send_file(filename, **options)
  File "/usr/local/lib/python2.7/dist-packages/flask/helpers.py", line 520, in send_file
    file = open(filename, 'rb')
IOError: [Errno 13] Permission denied: u'/var/www/flaskr/app/static/js/moment.min.js'
2013-12-16 11:48:21,787 ERROR: Exception on /static/img/aol.png [GET] [in /usr/local/lib/python2.7/dist-packages/flask/app.py:1423]
Traceback (most recent call last):
  File "/usr/local/lib/python2.7/dist-packages/flask/app.py", line 1817, in wsgi_app
    response = self.full_dispatch_request()
  File "/usr/local/lib/python2.7/dist-packages/flask/app.py", line 1477, in full_dispatch_request
    rv = self.handle_user_exception(e)
  File "/usr/local/lib/python2.7/dist-packages/flask/app.py", line 1381, in handle_user_exception
    reraise(exc_type, exc_value, tb)
  File "/usr/local/lib/python2.7/dist-packages/flask/app.py", line 1475, in full_dispatch_request
    rv = self.dispatch_request()
  File "/usr/local/lib/python2.7/dist-packages/flask/app.py", line 1461, in dispatch_request
    return self.view_functions[rule.endpoint](**req.view_args)
  File "/usr/local/lib/python2.7/dist-packages/flask/helpers.py", line 822, in send_static_file
    cache_timeout=cache_timeout)
  File "/usr/local/lib/python2.7/dist-packages/flask/helpers.py", line 616, in send_from_directory
    return send_file(filename, **options)
  File "/usr/local/lib/python2.7/dist-packages/flask/helpers.py", line 520, in send_file
    file = open(filename, 'rb')
IOError: [Errno 13] Permission denied: u'/var/www/flaskr/app/static/img/aol.png'
2013-12-16 11:48:21,789 ERROR: Exception on /static/img/myopenid.png [GET] [in /usr/local/lib/python2.7/dist-packages/flask/app.py:1423]
Traceback (most recent call last):
  File "/usr/local/lib/python2.7/dist-packages/flask/app.py", line 1817, in wsgi_app
    response = self.full_dispatch_request()
  File "/usr/local/lib/python2.7/dist-packages/flask/app.py", line 1477, in full_dispatch_request
    rv = self.handle_user_exception(e)
  File "/usr/local/lib/python2.7/dist-packages/flask/app.py", line 1381, in handle_user_exception
    reraise(exc_type, exc_value, tb)
  File "/usr/local/lib/python2.7/dist-packages/flask/app.py", line 1475, in full_dispatch_request
    rv = self.dispatch_request()
  File "/usr/local/lib/python2.7/dist-packages/flask/app.py", line 1461, in dispatch_request
    return self.view_functions[rule.endpoint](**req.view_args)
  File "/usr/local/lib/python2.7/dist-packages/flask/helpers.py", line 822, in send_static_file
    cache_timeout=cache_timeout)
  File "/usr/local/lib/python2.7/dist-packages/flask/helpers.py", line 616, in send_from_directory
    return send_file(filename, **options)
  File "/usr/local/lib/python2.7/dist-packages/flask/helpers.py", line 520, in send_file
    file = open(filename, 'rb')
IOError: [Errno 13] Permission denied: u'/var/www/flaskr/app/static/img/myopenid.png'
2013-12-16 11:48:21,989 ERROR: Exception on /static/img/google.png [GET] [in /usr/local/lib/python2.7/dist-packages/flask/app.py:1423]
Traceback (most recent call last):
  File "/usr/local/lib/python2.7/dist-packages/flask/app.py", line 1817, in wsgi_app
    response = self.full_dispatch_request()
  File "/usr/local/lib/python2.7/dist-packages/flask/app.py", line 1477, in full_dispatch_request
    rv = self.handle_user_exception(e)
  File "/usr/local/lib/python2.7/dist-packages/flask/app.py", line 1381, in handle_user_exception
    reraise(exc_type, exc_value, tb)
  File "/usr/local/lib/python2.7/dist-packages/flask/app.py", line 1475, in full_dispatch_request
    rv = self.dispatch_request()
  File "/usr/local/lib/python2.7/dist-packages/flask/app.py", line 1461, in dispatch_request
    return self.view_functions[rule.endpoint](**req.view_args)
  File "/usr/local/lib/python2.7/dist-packages/flask/helpers.py", line 822, in send_static_file
    cache_timeout=cache_timeout)
  File "/usr/local/lib/python2.7/dist-packages/flask/helpers.py", line 616, in send_from_directory
    return send_file(filename, **options)
  File "/usr/local/lib/python2.7/dist-packages/flask/helpers.py", line 520, in send_file
    file = open(filename, 'rb')
IOError: [Errno 13] Permission denied: u'/var/www/flaskr/app/static/img/google.png'
2013-12-16 12:07:46,493 INFO: microblog startup [in /var/www/flaskr/app/__init__.py:35]
2013-12-16 12:07:47,186 INFO: microblog startup [in /var/www/flaskr/app/__init__.py:35]
2013-12-16 12:08:32,674 ERROR: Exception on /index [GET] [in /usr/local/lib/python2.7/dist-packages/flask/app.py:1423]
Traceback (most recent call last):
  File "/usr/local/lib/python2.7/dist-packages/flask/app.py", line 1817, in wsgi_app
    response = self.full_dispatch_request()
  File "/usr/local/lib/python2.7/dist-packages/flask/app.py", line 1477, in full_dispatch_request
    rv = self.handle_user_exception(e)
  File "/usr/local/lib/python2.7/dist-packages/flask/app.py", line 1381, in handle_user_exception
    reraise(exc_type, exc_value, tb)
  File "/usr/local/lib/python2.7/dist-packages/flask/app.py", line 1473, in full_dispatch_request
    rv = self.preprocess_request()
  File "/usr/local/lib/python2.7/dist-packages/flask/app.py", line 1666, in preprocess_request
    rv = func()
  File "/var/www/flaskr/app/views.py", line 121, in before_request
    db.session.commit()
  File "/usr/lib/python2.7/dist-packages/sqlalchemy/orm/scoping.py", line 149, in do
    return getattr(self.registry(), name)(*args, **kwargs)
  File "/usr/lib/python2.7/dist-packages/sqlalchemy/orm/session.py", line 721, in commit
    self.transaction.commit()
  File "/usr/lib/python2.7/dist-packages/sqlalchemy/orm/session.py", line 354, in commit
    self._prepare_impl()
  File "/usr/lib/python2.7/dist-packages/sqlalchemy/orm/session.py", line 334, in _prepare_impl
    self.session.flush()
  File "/usr/lib/python2.7/dist-packages/sqlalchemy/orm/session.py", line 1818, in flush
    self._flush(objects)
  File "/usr/lib/python2.7/dist-packages/sqlalchemy/orm/session.py", line 1936, in _flush
    transaction.rollback(_capture_exception=True)
  File "/usr/lib/python2.7/dist-packages/sqlalchemy/util/langhelpers.py", line 58, in __exit__
    compat.reraise(exc_type, exc_value, exc_tb)
  File "/usr/lib/python2.7/dist-packages/sqlalchemy/orm/session.py", line 1900, in _flush
    flush_context.execute()
  File "/usr/lib/python2.7/dist-packages/sqlalchemy/orm/unitofwork.py", line 372, in execute
    rec.execute(self)
  File "/usr/lib/python2.7/dist-packages/sqlalchemy/orm/unitofwork.py", line 525, in execute
    uow
  File "/usr/lib/python2.7/dist-packages/sqlalchemy/orm/persistence.py", line 59, in save_obj
    mapper, table, update)
  File "/usr/lib/python2.7/dist-packages/sqlalchemy/orm/persistence.py", line 495, in _emit_update_statements
    execute(statement, params)
  File "/usr/lib/python2.7/dist-packages/sqlalchemy/engine/base.py", line 662, in execute
    params)
  File "/usr/lib/python2.7/dist-packages/sqlalchemy/engine/base.py", line 761, in _execute_clauseelement
    compiled_sql, distilled_params
  File "/usr/lib/python2.7/dist-packages/sqlalchemy/engine/base.py", line 874, in _execute_context
    context)
  File "/usr/lib/python2.7/dist-packages/sqlalchemy/engine/base.py", line 1024, in _handle_dbapi_exception
    exc_info
  File "/usr/lib/python2.7/dist-packages/sqlalchemy/util/compat.py", line 195, in raise_from_cause
    reraise(type(exception), exception, tb=exc_tb)
  File "/usr/lib/python2.7/dist-packages/sqlalchemy/engine/base.py", line 867, in _execute_context
    context)
  File "/usr/lib/python2.7/dist-packages/sqlalchemy/engine/default.py", line 324, in do_execute
    cursor.execute(statement, parameters)
OperationalError: (OperationalError) attempt to write a readonly database u'UPDATE user SET last_seen=? WHERE user.id = ?' ('2013-12-16 17:08:32.672844', 1)
2013-12-16 12:08:33,053 ERROR: Exception on /static/css/bootstrap-responsive.css [GET] [in /usr/local/lib/python2.7/dist-packages/flask/app.py:1423]
Traceback (most recent call last):
  File "/usr/local/lib/python2.7/dist-packages/flask/app.py", line 1817, in wsgi_app
    response = self.full_dispatch_request()
  File "/usr/local/lib/python2.7/dist-packages/flask/app.py", line 1477, in full_dispatch_request
    rv = self.handle_user_exception(e)
  File "/usr/local/lib/python2.7/dist-packages/flask/app.py", line 1381, in handle_user_exception
    reraise(exc_type, exc_value, tb)
  File "/usr/local/lib/python2.7/dist-packages/flask/app.py", line 1473, in full_dispatch_request
    rv = self.preprocess_request()
  File "/usr/local/lib/python2.7/dist-packages/flask/app.py", line 1666, in preprocess_request
    rv = func()
  File "/var/www/flaskr/app/views.py", line 121, in before_request
    db.session.commit()
  File "/usr/lib/python2.7/dist-packages/sqlalchemy/orm/scoping.py", line 149, in do
    return getattr(self.registry(), name)(*args, **kwargs)
  File "/usr/lib/python2.7/dist-packages/sqlalchemy/orm/session.py", line 721, in commit
    self.transaction.commit()
  File "/usr/lib/python2.7/dist-packages/sqlalchemy/orm/session.py", line 354, in commit
    self._prepare_impl()
  File "/usr/lib/python2.7/dist-packages/sqlalchemy/orm/session.py", line 334, in _prepare_impl
    self.session.flush()
  File "/usr/lib/python2.7/dist-packages/sqlalchemy/orm/session.py", line 1818, in flush
    self._flush(objects)
  File "/usr/lib/python2.7/dist-packages/sqlalchemy/orm/session.py", line 1936, in _flush
    transaction.rollback(_capture_exception=True)
  File "/usr/lib/python2.7/dist-packages/sqlalchemy/util/langhelpers.py", line 58, in __exit__
    compat.reraise(exc_type, exc_value, exc_tb)
  File "/usr/lib/python2.7/dist-packages/sqlalchemy/orm/session.py", line 1900, in _flush
    flush_context.execute()
  File "/usr/lib/python2.7/dist-packages/sqlalchemy/orm/unitofwork.py", line 372, in execute
    rec.execute(self)
  File "/usr/lib/python2.7/dist-packages/sqlalchemy/orm/unitofwork.py", line 525, in execute
    uow
  File "/usr/lib/python2.7/dist-packages/sqlalchemy/orm/persistence.py", line 59, in save_obj
    mapper, table, update)
  File "/usr/lib/python2.7/dist-packages/sqlalchemy/orm/persistence.py", line 495, in _emit_update_statements
    execute(statement, params)
  File "/usr/lib/python2.7/dist-packages/sqlalchemy/engine/base.py", line 662, in execute
    params)
  File "/usr/lib/python2.7/dist-packages/sqlalchemy/engine/base.py", line 761, in _execute_clauseelement
    compiled_sql, distilled_params
  File "/usr/lib/python2.7/dist-packages/sqlalchemy/engine/base.py", line 874, in _execute_context
    context)
  File "/usr/lib/python2.7/dist-packages/sqlalchemy/engine/base.py", line 1024, in _handle_dbapi_exception
    exc_info
  File "/usr/lib/python2.7/dist-packages/sqlalchemy/util/compat.py", line 195, in raise_from_cause
    reraise(type(exception), exception, tb=exc_tb)
  File "/usr/lib/python2.7/dist-packages/sqlalchemy/engine/base.py", line 867, in _execute_context
    context)
  File "/usr/lib/python2.7/dist-packages/sqlalchemy/engine/default.py", line 324, in do_execute
    cursor.execute(statement, parameters)
OperationalError: (OperationalError) attempt to write a readonly database u'UPDATE user SET last_seen=? WHERE user.id = ?' ('2013-12-16 17:08:33.052257', 1)
2013-12-16 12:08:33,053 ERROR: Exception on /static/css/bootstrap.min.css [GET] [in /usr/local/lib/python2.7/dist-packages/flask/app.py:1423]
Traceback (most recent call last):
  File "/usr/local/lib/python2.7/dist-packages/flask/app.py", line 1817, in wsgi_app
    response = self.full_dispatch_request()
  File "/usr/local/lib/python2.7/dist-packages/flask/app.py", line 1477, in full_dispatch_request
    rv = self.handle_user_exception(e)
  File "/usr/local/lib/python2.7/dist-packages/flask/app.py", line 1381, in handle_user_exception
    reraise(exc_type, exc_value, tb)
  File "/usr/local/lib/python2.7/dist-packages/flask/app.py", line 1473, in full_dispatch_request
    rv = self.preprocess_request()
  File "/usr/local/lib/python2.7/dist-packages/flask/app.py", line 1666, in preprocess_request
    rv = func()
  File "/var/www/flaskr/app/views.py", line 121, in before_request
    db.session.commit()
  File "/usr/lib/python2.7/dist-packages/sqlalchemy/orm/scoping.py", line 149, in do
    return getattr(self.registry(), name)(*args, **kwargs)
  File "/usr/lib/python2.7/dist-packages/sqlalchemy/orm/session.py", line 721, in commit
    self.transaction.commit()
  File "/usr/lib/python2.7/dist-packages/sqlalchemy/orm/session.py", line 354, in commit
    self._prepare_impl()
  File "/usr/lib/python2.7/dist-packages/sqlalchemy/orm/session.py", line 334, in _prepare_impl
    self.session.flush()
  File "/usr/lib/python2.7/dist-packages/sqlalchemy/orm/session.py", line 1818, in flush
    self._flush(objects)
  File "/usr/lib/python2.7/dist-packages/sqlalchemy/orm/session.py", line 1936, in _flush
    transaction.rollback(_capture_exception=True)
  File "/usr/lib/python2.7/dist-packages/sqlalchemy/util/langhelpers.py", line 58, in __exit__
    compat.reraise(exc_type, exc_value, exc_tb)
  File "/usr/lib/python2.7/dist-packages/sqlalchemy/orm/session.py", line 1900, in _flush
    flush_context.execute()
  File "/usr/lib/python2.7/dist-packages/sqlalchemy/orm/unitofwork.py", line 372, in execute
    rec.execute(self)
  File "/usr/lib/python2.7/dist-packages/sqlalchemy/orm/unitofwork.py", line 525, in execute
    uow
  File "/usr/lib/python2.7/dist-packages/sqlalchemy/orm/persistence.py", line 59, in save_obj
    mapper, table, update)
  File "/usr/lib/python2.7/dist-packages/sqlalchemy/orm/persistence.py", line 495, in _emit_update_statements
    execute(statement, params)
  File "/usr/lib/python2.7/dist-packages/sqlalchemy/engine/base.py", line 662, in execute
    params)
  File "/usr/lib/python2.7/dist-packages/sqlalchemy/engine/base.py", line 761, in _execute_clauseelement
    compiled_sql, distilled_params
  File "/usr/lib/python2.7/dist-packages/sqlalchemy/engine/base.py", line 874, in _execute_context
    context)
  File "/usr/lib/python2.7/dist-packages/sqlalchemy/engine/base.py", line 1024, in _handle_dbapi_exception
    exc_info
  File "/usr/lib/python2.7/dist-packages/sqlalchemy/util/compat.py", line 195, in raise_from_cause
    reraise(type(exception), exception, tb=exc_tb)
  File "/usr/lib/python2.7/dist-packages/sqlalchemy/engine/base.py", line 867, in _execute_context
    context)
  File "/usr/lib/python2.7/dist-packages/sqlalchemy/engine/default.py", line 324, in do_execute
    cursor.execute(statement, parameters)
OperationalError: (OperationalError) attempt to write a readonly database u'UPDATE user SET last_seen=? WHERE user.id = ?' ('2013-12-16 17:08:33.051816', 1)
2013-12-16 12:08:33,065 ERROR: Exception on /static/js/bootstrap.min.js [GET] [in /usr/local/lib/python2.7/dist-packages/flask/app.py:1423]
Traceback (most recent call last):
  File "/usr/local/lib/python2.7/dist-packages/flask/app.py", line 1817, in wsgi_app
    response = self.full_dispatch_request()
  File "/usr/local/lib/python2.7/dist-packages/flask/app.py", line 1477, in full_dispatch_request
    rv = self.handle_user_exception(e)
  File "/usr/local/lib/python2.7/dist-packages/flask/app.py", line 1381, in handle_user_exception
    reraise(exc_type, exc_value, tb)
  File "/usr/local/lib/python2.7/dist-packages/flask/app.py", line 1473, in full_dispatch_request
    rv = self.preprocess_request()
  File "/usr/local/lib/python2.7/dist-packages/flask/app.py", line 1666, in preprocess_request
    rv = func()
  File "/var/www/flaskr/app/views.py", line 121, in before_request
    db.session.commit()
  File "/usr/lib/python2.7/dist-packages/sqlalchemy/orm/scoping.py", line 149, in do
    return getattr(self.registry(), name)(*args, **kwargs)
  File "/usr/lib/python2.7/dist-packages/sqlalchemy/orm/session.py", line 721, in commit
    self.transaction.commit()
  File "/usr/lib/python2.7/dist-packages/sqlalchemy/orm/session.py", line 354, in commit
    self._prepare_impl()
  File "/usr/lib/python2.7/dist-packages/sqlalchemy/orm/session.py", line 334, in _prepare_impl
    self.session.flush()
  File "/usr/lib/python2.7/dist-packages/sqlalchemy/orm/session.py", line 1818, in flush
    self._flush(objects)
  File "/usr/lib/python2.7/dist-packages/sqlalchemy/orm/session.py", line 1936, in _flush
    transaction.rollback(_capture_exception=True)
  File "/usr/lib/python2.7/dist-packages/sqlalchemy/util/langhelpers.py", line 58, in __exit__
    compat.reraise(exc_type, exc_value, exc_tb)
  File "/usr/lib/python2.7/dist-packages/sqlalchemy/orm/session.py", line 1900, in _flush
    flush_context.execute()
  File "/usr/lib/python2.7/dist-packages/sqlalchemy/orm/unitofwork.py", line 372, in execute
    rec.execute(self)
  File "/usr/lib/python2.7/dist-packages/sqlalchemy/orm/unitofwork.py", line 525, in execute
    uow
  File "/usr/lib/python2.7/dist-packages/sqlalchemy/orm/persistence.py", line 59, in save_obj
    mapper, table, update)
  File "/usr/lib/python2.7/dist-packages/sqlalchemy/orm/persistence.py", line 495, in _emit_update_statements
    execute(statement, params)
  File "/usr/lib/python2.7/dist-packages/sqlalchemy/engine/base.py", line 662, in execute
    params)
  File "/usr/lib/python2.7/dist-packages/sqlalchemy/engine/base.py", line 761, in _execute_clauseelement
    compiled_sql, distilled_params
  File "/usr/lib/python2.7/dist-packages/sqlalchemy/engine/base.py", line 874, in _execute_context
    context)
  File "/usr/lib/python2.7/dist-packages/sqlalchemy/engine/base.py", line 1024, in _handle_dbapi_exception
    exc_info
  File "/usr/lib/python2.7/dist-packages/sqlalchemy/util/compat.py", line 195, in raise_from_cause
    reraise(type(exception), exception, tb=exc_tb)
  File "/usr/lib/python2.7/dist-packages/sqlalchemy/engine/base.py", line 867, in _execute_context
    context)
  File "/usr/lib/python2.7/dist-packages/sqlalchemy/engine/default.py", line 324, in do_execute
    cursor.execute(statement, parameters)
OperationalError: (OperationalError) attempt to write a readonly database u'UPDATE user SET last_seen=? WHERE user.id = ?' ('2013-12-16 17:08:33.064208', 1)
2013-12-16 12:08:33,069 ERROR: Exception on /static/js/moment.min.js [GET] [in /usr/local/lib/python2.7/dist-packages/flask/app.py:1423]
Traceback (most recent call last):
  File "/usr/local/lib/python2.7/dist-packages/flask/app.py", line 1817, in wsgi_app
    response = self.full_dispatch_request()
  File "/usr/local/lib/python2.7/dist-packages/flask/app.py", line 1477, in full_dispatch_request
    rv = self.handle_user_exception(e)
  File "/usr/local/lib/python2.7/dist-packages/flask/app.py", line 1381, in handle_user_exception
    reraise(exc_type, exc_value, tb)
  File "/usr/local/lib/python2.7/dist-packages/flask/app.py", line 1473, in full_dispatch_request
    rv = self.preprocess_request()
  File "/usr/local/lib/python2.7/dist-packages/flask/app.py", line 1666, in preprocess_request
    rv = func()
  File "/var/www/flaskr/app/views.py", line 121, in before_request
    db.session.commit()
  File "/usr/lib/python2.7/dist-packages/sqlalchemy/orm/scoping.py", line 149, in do
    return getattr(self.registry(), name)(*args, **kwargs)
  File "/usr/lib/python2.7/dist-packages/sqlalchemy/orm/session.py", line 721, in commit
    self.transaction.commit()
  File "/usr/lib/python2.7/dist-packages/sqlalchemy/orm/session.py", line 354, in commit
    self._prepare_impl()
  File "/usr/lib/python2.7/dist-packages/sqlalchemy/orm/session.py", line 334, in _prepare_impl
    self.session.flush()
  File "/usr/lib/python2.7/dist-packages/sqlalchemy/orm/session.py", line 1818, in flush
    self._flush(objects)
  File "/usr/lib/python2.7/dist-packages/sqlalchemy/orm/session.py", line 1936, in _flush
    transaction.rollback(_capture_exception=True)
  File "/usr/lib/python2.7/dist-packages/sqlalchemy/util/langhelpers.py", line 58, in __exit__
    compat.reraise(exc_type, exc_value, exc_tb)
  File "/usr/lib/python2.7/dist-packages/sqlalchemy/orm/session.py", line 1900, in _flush
    flush_context.execute()
  File "/usr/lib/python2.7/dist-packages/sqlalchemy/orm/unitofwork.py", line 372, in execute
    rec.execute(self)
  File "/usr/lib/python2.7/dist-packages/sqlalchemy/orm/unitofwork.py", line 525, in execute
    uow
  File "/usr/lib/python2.7/dist-packages/sqlalchemy/orm/persistence.py", line 59, in save_obj
    mapper, table, update)
  File "/usr/lib/python2.7/dist-packages/sqlalchemy/orm/persistence.py", line 495, in _emit_update_statements
    execute(statement, params)
  File "/usr/lib/python2.7/dist-packages/sqlalchemy/engine/base.py", line 662, in execute
    params)
  File "/usr/lib/python2.7/dist-packages/sqlalchemy/engine/base.py", line 761, in _execute_clauseelement
    compiled_sql, distilled_params
  File "/usr/lib/python2.7/dist-packages/sqlalchemy/engine/base.py", line 874, in _execute_context
    context)
  File "/usr/lib/python2.7/dist-packages/sqlalchemy/engine/base.py", line 1024, in _handle_dbapi_exception
    exc_info
  File "/usr/lib/python2.7/dist-packages/sqlalchemy/util/compat.py", line 195, in raise_from_cause
    reraise(type(exception), exception, tb=exc_tb)
  File "/usr/lib/python2.7/dist-packages/sqlalchemy/engine/base.py", line 867, in _execute_context
    context)
  File "/usr/lib/python2.7/dist-packages/sqlalchemy/engine/default.py", line 324, in do_execute
    cursor.execute(statement, parameters)
OperationalError: (OperationalError) attempt to write a readonly database u'UPDATE user SET last_seen=? WHERE user.id = ?' ('2013-12-16 17:08:33.066224', 1)
2013-12-16 13:05:35,194 INFO: microblog startup [in /var/www/flaskr/app/__init__.py:35]
2013-12-16 13:05:35,446 INFO: microblog startup [in /var/www/flaskr/app/__init__.py:35]
2013-12-16 13:08:02,560 INFO: microblog startup [in /var/www/flaskr/app/__init__.py:35]
2013-12-16 13:08:03,006 INFO: microblog startup [in /var/www/flaskr/app/__init__.py:35]
2013-12-16 13:08:58,614 INFO: microblog startup [in /var/www/flaskr/app/__init__.py:35]
2013-12-16 13:08:59,070 INFO: microblog startup [in /var/www/flaskr/app/__init__.py:35]
2013-12-16 13:34:12,505 INFO: microblog startup [in /var/www/flaskr/app/__init__.py:35]
2013-12-16 13:34:16,562 INFO: microblog startup [in /var/www/flaskr/app/__init__.py:35]
2013-12-16 13:34:46,460 INFO: microblog startup [in /var/wwwcopy/flaskr/app/__init__.py:35]
2013-12-16 13:34:46,800 INFO: microblog startup [in /var/wwwcopy/flaskr/app/__init__.py:35]
2013-12-16 13:38:16,595 INFO: microblog startup [in /var/wwwcopy/flaskr/app/__init__.py:35]
2013-12-16 13:38:16,855 INFO: microblog startup [in /var/wwwcopy/flaskr/app/__init__.py:35]
2013-12-16 13:40:09,084 INFO: microblog startup [in /var/wwwcopy/flaskr/app/__init__.py:35]
2013-12-16 13:40:35,605 INFO: microblog startup [in /var/wwwcopy/flaskr/app/__init__.py:35]
2013-12-16 13:40:59,075 INFO: microblog startup [in /var/wwwcopy/flaskr/app/__init__.py:35]
2013-12-16 13:41:22,533 INFO: microblog startup [in /var/wwwcopy/flaskr/app/__init__.py:35]
2013-12-16 13:43:15,510 ERROR: Exception on /user/petrovovitch [GET] [in /usr/local/lib/python2.7/dist-packages/flask/app.py:1423]
Traceback (most recent call last):
  File "/usr/local/lib/python2.7/dist-packages/flask/app.py", line 1817, in wsgi_app
    response = self.full_dispatch_request()
  File "/usr/local/lib/python2.7/dist-packages/flask/app.py", line 1477, in full_dispatch_request
    rv = self.handle_user_exception(e)
  File "/usr/local/lib/python2.7/dist-packages/flask/app.py", line 1381, in handle_user_exception
    reraise(exc_type, exc_value, tb)
  File "/usr/local/lib/python2.7/dist-packages/flask/app.py", line 1475, in full_dispatch_request
    rv = self.dispatch_request()
  File "/usr/local/lib/python2.7/dist-packages/flask/app.py", line 1461, in dispatch_request
    return self.view_functions[rule.endpoint](**req.view_args)
  File "/usr/local/lib/python2.7/dist-packages/flask_login.py", line 658, in decorated_view
    return func(*args, **kwargs)
  File "/var/www/flaskr/app/views.py", line 141, in user
    posts=posts)
  File "/usr/local/lib/python2.7/dist-packages/flask/templating.py", line 127, in render_template
    return _render(ctx.app.jinja_env.get_or_select_template(template_name_or_list),
  File "/usr/local/lib/python2.7/dist-packages/jinja2/environment.py", line 830, in get_or_select_template
    return self.get_template(template_name_or_list, parent, globals)
  File "/usr/local/lib/python2.7/dist-packages/jinja2/environment.py", line 791, in get_template
    return self._load_template(name, self.make_globals(globals))
  File "/usr/local/lib/python2.7/dist-packages/jinja2/environment.py", line 765, in _load_template
    template = self.loader.load(self, name, globals)
  File "/usr/local/lib/python2.7/dist-packages/jinja2/loaders.py", line 113, in load
    source, filename, uptodate = self.get_source(environment, name)
  File "/usr/local/lib/python2.7/dist-packages/flask/templating.py", line 64, in get_source
    raise TemplateNotFound(template)
TemplateNotFound: user.html
2013-12-16 13:43:21,084 ERROR: Exception on /favicon.ico [GET] [in /usr/local/lib/python2.7/dist-packages/flask/app.py:1423]
Traceback (most recent call last):
  File "/usr/local/lib/python2.7/dist-packages/flask/app.py", line 1817, in wsgi_app
    response = self.full_dispatch_request()
  File "/usr/local/lib/python2.7/dist-packages/flask/app.py", line 1477, in full_dispatch_request
    rv = self.handle_user_exception(e)
  File "/usr/local/lib/python2.7/dist-packages/flask/app.py", line 1370, in handle_user_exception
    return self.handle_http_exception(e)
  File "/usr/local/lib/python2.7/dist-packages/flask/app.py", line 1330, in handle_http_exception
    return handler(e)
  File "/var/www/flaskr/app/views.py", line 165, in internal_error
    return render_template('404.html'), 404
  File "/usr/local/lib/python2.7/dist-packages/flask/templating.py", line 127, in render_template
    return _render(ctx.app.jinja_env.get_or_select_template(template_name_or_list),
  File "/usr/local/lib/python2.7/dist-packages/jinja2/environment.py", line 830, in get_or_select_template
    return self.get_template(template_name_or_list, parent, globals)
  File "/usr/local/lib/python2.7/dist-packages/jinja2/environment.py", line 791, in get_template
    return self._load_template(name, self.make_globals(globals))
  File "/usr/local/lib/python2.7/dist-packages/jinja2/environment.py", line 765, in _load_template
    template = self.loader.load(self, name, globals)
  File "/usr/local/lib/python2.7/dist-packages/jinja2/loaders.py", line 113, in load
    source, filename, uptodate = self.get_source(environment, name)
  File "/usr/local/lib/python2.7/dist-packages/flask/templating.py", line 64, in get_source
    raise TemplateNotFound(template)
TemplateNotFound: 404.html
2013-12-16 13:43:26,367 ERROR: Exception on /favicon.ico [GET] [in /usr/local/lib/python2.7/dist-packages/flask/app.py:1423]
Traceback (most recent call last):
  File "/usr/local/lib/python2.7/dist-packages/flask/app.py", line 1817, in wsgi_app
    response = self.full_dispatch_request()
  File "/usr/local/lib/python2.7/dist-packages/flask/app.py", line 1477, in full_dispatch_request
    rv = self.handle_user_exception(e)
  File "/usr/local/lib/python2.7/dist-packages/flask/app.py", line 1370, in handle_user_exception
    return self.handle_http_exception(e)
  File "/usr/local/lib/python2.7/dist-packages/flask/app.py", line 1330, in handle_http_exception
    return handler(e)
  File "/var/www/flaskr/app/views.py", line 165, in internal_error
    return render_template('404.html'), 404
  File "/usr/local/lib/python2.7/dist-packages/flask/templating.py", line 127, in render_template
    return _render(ctx.app.jinja_env.get_or_select_template(template_name_or_list),
  File "/usr/local/lib/python2.7/dist-packages/jinja2/environment.py", line 830, in get_or_select_template
    return self.get_template(template_name_or_list, parent, globals)
  File "/usr/local/lib/python2.7/dist-packages/jinja2/environment.py", line 791, in get_template
    return self._load_template(name, self.make_globals(globals))
  File "/usr/local/lib/python2.7/dist-packages/jinja2/environment.py", line 765, in _load_template
    template = self.loader.load(self, name, globals)
  File "/usr/local/lib/python2.7/dist-packages/jinja2/loaders.py", line 113, in load
    source, filename, uptodate = self.get_source(environment, name)
  File "/usr/local/lib/python2.7/dist-packages/flask/templating.py", line 64, in get_source
    raise TemplateNotFound(template)
TemplateNotFound: 404.html
2013-12-16 13:44:05,177 ERROR: Exception on / [GET] [in /usr/local/lib/python2.7/dist-packages/flask/app.py:1423]
Traceback (most recent call last):
  File "/usr/local/lib/python2.7/dist-packages/flask/app.py", line 1817, in wsgi_app
    response = self.full_dispatch_request()
  File "/usr/local/lib/python2.7/dist-packages/flask/app.py", line 1477, in full_dispatch_request
    rv = self.handle_user_exception(e)
  File "/usr/local/lib/python2.7/dist-packages/flask/app.py", line 1381, in handle_user_exception
    reraise(exc_type, exc_value, tb)
  File "/usr/local/lib/python2.7/dist-packages/flask/app.py", line 1475, in full_dispatch_request
    rv = self.dispatch_request()
  File "/usr/local/lib/python2.7/dist-packages/flask/app.py", line 1461, in dispatch_request
    return self.view_functions[rule.endpoint](**req.view_args)
  File "/usr/local/lib/python2.7/dist-packages/flask_login.py", line 658, in decorated_view
    return func(*args, **kwargs)
  File "/var/www/flaskr/app/views.py", line 28, in index
    posts=posts)
  File "/usr/local/lib/python2.7/dist-packages/flask/templating.py", line 127, in render_template
    return _render(ctx.app.jinja_env.get_or_select_template(template_name_or_list),
  File "/usr/local/lib/python2.7/dist-packages/jinja2/environment.py", line 830, in get_or_select_template
    return self.get_template(template_name_or_list, parent, globals)
  File "/usr/local/lib/python2.7/dist-packages/jinja2/environment.py", line 791, in get_template
    return self._load_template(name, self.make_globals(globals))
  File "/usr/local/lib/python2.7/dist-packages/jinja2/environment.py", line 765, in _load_template
    template = self.loader.load(self, name, globals)
  File "/usr/local/lib/python2.7/dist-packages/jinja2/loaders.py", line 113, in load
    source, filename, uptodate = self.get_source(environment, name)
  File "/usr/local/lib/python2.7/dist-packages/flask/templating.py", line 64, in get_source
    raise TemplateNotFound(template)
TemplateNotFound: index.html
2013-12-16 13:44:10,732 ERROR: Exception on /favicon.ico [GET] [in /usr/local/lib/python2.7/dist-packages/flask/app.py:1423]
Traceback (most recent call last):
  File "/usr/local/lib/python2.7/dist-packages/flask/app.py", line 1817, in wsgi_app
    response = self.full_dispatch_request()
  File "/usr/local/lib/python2.7/dist-packages/flask/app.py", line 1477, in full_dispatch_request
    rv = self.handle_user_exception(e)
  File "/usr/local/lib/python2.7/dist-packages/flask/app.py", line 1370, in handle_user_exception
    return self.handle_http_exception(e)
  File "/usr/local/lib/python2.7/dist-packages/flask/app.py", line 1330, in handle_http_exception
    return handler(e)
  File "/var/www/flaskr/app/views.py", line 165, in internal_error
    return render_template('404.html'), 404
  File "/usr/local/lib/python2.7/dist-packages/flask/templating.py", line 127, in render_template
    return _render(ctx.app.jinja_env.get_or_select_template(template_name_or_list),
  File "/usr/local/lib/python2.7/dist-packages/jinja2/environment.py", line 830, in get_or_select_template
    return self.get_template(template_name_or_list, parent, globals)
  File "/usr/local/lib/python2.7/dist-packages/jinja2/environment.py", line 791, in get_template
    return self._load_template(name, self.make_globals(globals))
  File "/usr/local/lib/python2.7/dist-packages/jinja2/environment.py", line 765, in _load_template
    template = self.loader.load(self, name, globals)
  File "/usr/local/lib/python2.7/dist-packages/jinja2/loaders.py", line 113, in load
    source, filename, uptodate = self.get_source(environment, name)
  File "/usr/local/lib/python2.7/dist-packages/flask/templating.py", line 64, in get_source
    raise TemplateNotFound(template)
TemplateNotFound: 404.html
2013-12-16 13:44:16,002 ERROR: Exception on /favicon.ico [GET] [in /usr/local/lib/python2.7/dist-packages/flask/app.py:1423]
Traceback (most recent call last):
  File "/usr/local/lib/python2.7/dist-packages/flask/app.py", line 1817, in wsgi_app
    response = self.full_dispatch_request()
  File "/usr/local/lib/python2.7/dist-packages/flask/app.py", line 1477, in full_dispatch_request
    rv = self.handle_user_exception(e)
  File "/usr/local/lib/python2.7/dist-packages/flask/app.py", line 1370, in handle_user_exception
    return self.handle_http_exception(e)
  File "/usr/local/lib/python2.7/dist-packages/flask/app.py", line 1330, in handle_http_exception
    return handler(e)
  File "/var/www/flaskr/app/views.py", line 165, in internal_error
    return render_template('404.html'), 404
  File "/usr/local/lib/python2.7/dist-packages/flask/templating.py", line 127, in render_template
    return _render(ctx.app.jinja_env.get_or_select_template(template_name_or_list),
  File "/usr/local/lib/python2.7/dist-packages/jinja2/environment.py", line 830, in get_or_select_template
    return self.get_template(template_name_or_list, parent, globals)
  File "/usr/local/lib/python2.7/dist-packages/jinja2/environment.py", line 791, in get_template
    return self._load_template(name, self.make_globals(globals))
  File "/usr/local/lib/python2.7/dist-packages/jinja2/environment.py", line 765, in _load_template
    template = self.loader.load(self, name, globals)
  File "/usr/local/lib/python2.7/dist-packages/jinja2/loaders.py", line 113, in load
    source, filename, uptodate = self.get_source(environment, name)
  File "/usr/local/lib/python2.7/dist-packages/flask/templating.py", line 64, in get_source
    raise TemplateNotFound(template)
TemplateNotFound: 404.html
2013-12-16 13:44:55,079 INFO: microblog startup [in /var/wwwcopy/flaskr/app/__init__.py:35]
2013-12-16 13:44:55,330 INFO: microblog startup [in /var/wwwcopy/flaskr/app/__init__.py:35]
2013-12-16 13:47:06,612 INFO: microblog startup [in /var/www/flaskr/app/__init__.py:35]
2013-12-16 13:47:07,248 INFO: microblog startup [in /var/www/flaskr/app/__init__.py:35]
2013-12-16 13:47:38,211 INFO: microblog startup [in /var/www/flaskr/app/__init__.py:35]
2013-12-16 13:47:38,809 INFO: microblog startup [in /var/www/flaskr/app/__init__.py:35]
2013-12-16 13:53:16,590 INFO: microblog startup [in /var/www/flaskr/app/__init__.py:35]
2013-12-16 13:53:17,201 INFO: microblog startup [in /var/www/flaskr/app/__init__.py:35]
2013-12-16 14:05:09,443 INFO: microblog startup [in /var/www/myapp/flaskr/app/__init__.py:35]
2013-12-16 14:06:03,274 INFO: microblog startup [in /var/www/myapp/flaskr/app/__init__.py:35]
2013-12-16 14:06:03,811 INFO: microblog startup [in /var/www/myapp/flaskr/app/__init__.py:35]
